2025-09-07 20:05:32,589 - core.connection_manager - ERROR - [connection_manager.py:183 - print_active_connections()] - Ебань
2025-09-07 20:05:32,591 - core.connection_manager - ERROR - [connection_manager.py:183 - print_active_connections()] - Ебань
2025-09-07 20:05:32,592 - core.connection_manager - ERROR - [connection_manager.py:183 - print_active_connections()] - Ебань
2025-09-07 20:05:32,594 - core.connection_manager - ERROR - [connection_manager.py:183 - print_active_connections()] - Ебань
2025-09-07 20:05:32,595 - core.connection_manager - ERROR - [connection_manager.py:183 - print_active_connections()] - Ебань
2025-09-07 20:05:46,093 - app.http.routes.web_socket - ERROR - [web_socket.py:36 - websocket()] - 1830913972:1e13e4b3-4d23-4847-a574-3e8999829792: 'ConnectionManager' object has no attribute 'active_connections'
2025-09-07 20:05:46,096 - app.http.routes.web_socket - ERROR - [web_socket.py:36 - websocket()] - 1830913972:d44dfaf9-7d0a-495d-9d57-b5d246960064: 'ConnectionManager' object has no attribute 'active_connections'
2025-09-07 20:05:46,100 - app.http.routes.web_socket - ERROR - [web_socket.py:36 - websocket()] - 1830913972:65508ac0-f11e-4216-b34b-672bae58ed16: 'ConnectionManager' object has no attribute 'active_connections'
2025-09-07 20:05:46,100 - app.http.routes.web_socket - ERROR - [web_socket.py:36 - websocket()] - 1830913972:e5e6aa74-701e-4e83-a276-8a1a99344ba2: 'ConnectionManager' object has no attribute 'active_connections'
2025-09-07 20:05:46,101 - app.http.routes.web_socket - ERROR - [web_socket.py:36 - websocket()] - 1830913972:6f7ba471-535f-42d0-bc4b-8704365019f9: 'ConnectionManager' object has no attribute 'active_connections'
2025-09-08 01:25:56,073 - app.llm_client.deepseek.llm_client_deepseek - ERROR - [llm_client_deepseek.py:71 - _validate()] - Failed to validate DeepSeekClient error: 'DeepSeekWSClient' object has no attribute '_LLMClient__config_ai'
2025-09-08 01:25:56,099 - app.llm_client.deepseek.llm_client_deepseek - ERROR - [llm_client_deepseek.py:71 - _validate()] - Failed to validate DeepSeekClient error: 'DeepSeekWSClient' object has no attribute '_LLMClient__config_ai'
2025-09-08 01:25:56,121 - app.llm_client.deepseek.llm_client_deepseek - ERROR - [llm_client_deepseek.py:71 - _validate()] - Failed to validate DeepSeekClient error: 'DeepSeekWSClient' object has no attribute '_LLMClient__config_ai'
2025-09-08 01:25:56,141 - app.llm_client.deepseek.llm_client_deepseek - ERROR - [llm_client_deepseek.py:71 - _validate()] - Failed to validate DeepSeekClient error: 'DeepSeekWSClient' object has no attribute '_LLMClient__config_ai'
2025-09-08 01:25:56,162 - app.llm_client.deepseek.llm_client_deepseek - ERROR - [llm_client_deepseek.py:71 - _validate()] - Failed to validate DeepSeekClient error: 'DeepSeekWSClient' object has no attribute '_LLMClient__config_ai'
2025-09-08 01:28:47,672 - app.llm_client.deepseek.llm_client_deepseek - ERROR - [llm_client_deepseek.py:72 - _validate()] - Failed to validate DeepSeekClient error: Keys file not found: D:\ART\PY\bot\AI-assistant-for-patents-telegram-app\services\llm_client_service\storage\key\deepseek\deepseek_auth_key.json
2025-09-08 01:28:47,817 - app.llm_client.deepseek.llm_client_deepseek - ERROR - [llm_client_deepseek.py:72 - _validate()] - Failed to validate DeepSeekClient error: Keys file not found: D:\ART\PY\bot\AI-assistant-for-patents-telegram-app\services\llm_client_service\storage\key\deepseek\deepseek_auth_key.json
2025-09-08 01:28:47,920 - app.llm_client.deepseek.llm_client_deepseek - ERROR - [llm_client_deepseek.py:72 - _validate()] - Failed to validate DeepSeekClient error: Keys file not found: D:\ART\PY\bot\AI-assistant-for-patents-telegram-app\services\llm_client_service\storage\key\deepseek\deepseek_auth_key.json
2025-09-08 01:28:47,997 - app.llm_client.deepseek.llm_client_deepseek - ERROR - [llm_client_deepseek.py:72 - _validate()] - Failed to validate DeepSeekClient error: Keys file not found: D:\ART\PY\bot\AI-assistant-for-patents-telegram-app\services\llm_client_service\storage\key\deepseek\deepseek_auth_key.json
2025-09-08 01:28:48,217 - app.llm_client.deepseek.llm_client_deepseek - ERROR - [llm_client_deepseek.py:72 - _validate()] - Failed to validate DeepSeekClient error: Keys file not found: D:\ART\PY\bot\AI-assistant-for-patents-telegram-app\services\llm_client_service\storage\key\deepseek\deepseek_auth_key.json
2025-09-08 01:37:22,318 - app.llm_client.deepseek.llm_client_deepseek - ERROR - [llm_client_deepseek.py:72 - _validate()] - Failed to validate DeepSeekClient error: Keys file not found: D:\ART\PY\bot\AI-assistant-for-patents-telegram-app\services\llm_client_service\storage\key\deepseek\deepseek_auth_key.json
2025-09-08 01:37:22,364 - app.llm_client.deepseek.llm_client_deepseek - ERROR - [llm_client_deepseek.py:72 - _validate()] - Failed to validate DeepSeekClient error: Keys file not found: D:\ART\PY\bot\AI-assistant-for-patents-telegram-app\services\llm_client_service\storage\key\deepseek\deepseek_auth_key.json
2025-09-08 01:37:22,446 - app.llm_client.deepseek.llm_client_deepseek - ERROR - [llm_client_deepseek.py:72 - _validate()] - Failed to validate DeepSeekClient error: Keys file not found: D:\ART\PY\bot\AI-assistant-for-patents-telegram-app\services\llm_client_service\storage\key\deepseek\deepseek_auth_key.json
2025-09-08 01:37:22,504 - app.llm_client.deepseek.llm_client_deepseek - ERROR - [llm_client_deepseek.py:72 - _validate()] - Failed to validate DeepSeekClient error: Keys file not found: D:\ART\PY\bot\AI-assistant-for-patents-telegram-app\services\llm_client_service\storage\key\deepseek\deepseek_auth_key.json
2025-09-08 01:37:22,542 - app.llm_client.deepseek.llm_client_deepseek - ERROR - [llm_client_deepseek.py:72 - _validate()] - Failed to validate DeepSeekClient error: Keys file not found: D:\ART\PY\bot\AI-assistant-for-patents-telegram-app\services\llm_client_service\storage\key\deepseek\deepseek_auth_key.json
2025-09-08 01:46:32,927 - app.llm_client.deepseek.llm_client_deepseek - ERROR - [llm_client_deepseek.py:72 - _validate()] - Failed to validate DeepSeekClient error: Keys file not found: D:\ART\PY\bot\AI-assistant-for-patents-telegram-app\services\llm_client_service\storage\key\deepseek\deepseek_auth_key.json
2025-09-08 01:46:32,993 - app.llm_client.deepseek.llm_client_deepseek - ERROR - [llm_client_deepseek.py:72 - _validate()] - Failed to validate DeepSeekClient error: Keys file not found: D:\ART\PY\bot\AI-assistant-for-patents-telegram-app\services\llm_client_service\storage\key\deepseek\deepseek_auth_key.json
2025-09-08 01:46:33,050 - app.llm_client.deepseek.llm_client_deepseek - ERROR - [llm_client_deepseek.py:72 - _validate()] - Failed to validate DeepSeekClient error: Keys file not found: D:\ART\PY\bot\AI-assistant-for-patents-telegram-app\services\llm_client_service\storage\key\deepseek\deepseek_auth_key.json
2025-09-08 01:46:33,068 - app.llm_client.deepseek.llm_client_deepseek - ERROR - [llm_client_deepseek.py:72 - _validate()] - Failed to validate DeepSeekClient error: Keys file not found: D:\ART\PY\bot\AI-assistant-for-patents-telegram-app\services\llm_client_service\storage\key\deepseek\deepseek_auth_key.json
2025-09-08 01:46:33,143 - app.llm_client.deepseek.llm_client_deepseek - ERROR - [llm_client_deepseek.py:72 - _validate()] - Failed to validate DeepSeekClient error: Keys file not found: D:\ART\PY\bot\AI-assistant-for-patents-telegram-app\services\llm_client_service\storage\key\deepseek\deepseek_auth_key.json
2025-09-08 02:08:51,414 - app.llm_client.deepseek.llm_client_deepseek - ERROR - [llm_client_deepseek.py:72 - _validate()] - Failed to validate DeepSeekClient error: Keys file not found: .storage\key\deepseek\deepseek_auth_key.json
2025-09-08 02:08:51,458 - app.llm_client.deepseek.llm_client_deepseek - ERROR - [llm_client_deepseek.py:72 - _validate()] - Failed to validate DeepSeekClient error: Keys file not found: .storage\key\deepseek\deepseek_auth_key.json
2025-09-08 02:08:51,468 - app.llm_client.deepseek.llm_client_deepseek - ERROR - [llm_client_deepseek.py:72 - _validate()] - Failed to validate DeepSeekClient error: Keys file not found: .storage\key\deepseek\deepseek_auth_key.json
2025-09-08 02:08:51,485 - app.llm_client.deepseek.llm_client_deepseek - ERROR - [llm_client_deepseek.py:72 - _validate()] - Failed to validate DeepSeekClient error: Keys file not found: .storage\key\deepseek\deepseek_auth_key.json
2025-09-08 02:08:51,493 - app.llm_client.deepseek.llm_client_deepseek - ERROR - [llm_client_deepseek.py:72 - _validate()] - Failed to validate DeepSeekClient error: Keys file not found: .storage\key\deepseek\deepseek_auth_key.json
2025-09-08 02:31:53,718 - app.llm_client.deepseek.llm_client_deepseek - ERROR - [llm_client_deepseek.py:72 - _validate()] - Failed to validate DeepSeekClient error: Keys file not found: D:\ART\InnodivingPro\MVP1.8.1\AI-assistant-for-patents-telegram-app\services\llm_client_service\.storage\key\deepseek\deepseek_auth_key.json
2025-09-08 02:31:53,728 - app.llm_client.deepseek.llm_client_deepseek - ERROR - [llm_client_deepseek.py:72 - _validate()] - Failed to validate DeepSeekClient error: Keys file not found: D:\ART\InnodivingPro\MVP1.8.1\AI-assistant-for-patents-telegram-app\services\llm_client_service\.storage\key\deepseek\deepseek_auth_key.json
2025-09-08 02:31:53,734 - app.llm_client.deepseek.llm_client_deepseek - ERROR - [llm_client_deepseek.py:72 - _validate()] - Failed to validate DeepSeekClient error: Keys file not found: D:\ART\InnodivingPro\MVP1.8.1\AI-assistant-for-patents-telegram-app\services\llm_client_service\.storage\key\deepseek\deepseek_auth_key.json
2025-09-08 02:31:53,741 - app.llm_client.deepseek.llm_client_deepseek - ERROR - [llm_client_deepseek.py:72 - _validate()] - Failed to validate DeepSeekClient error: Keys file not found: D:\ART\InnodivingPro\MVP1.8.1\AI-assistant-for-patents-telegram-app\services\llm_client_service\.storage\key\deepseek\deepseek_auth_key.json
2025-09-08 02:31:53,754 - app.llm_client.deepseek.llm_client_deepseek - ERROR - [llm_client_deepseek.py:72 - _validate()] - Failed to validate DeepSeekClient error: Keys file not found: D:\ART\InnodivingPro\MVP1.8.1\AI-assistant-for-patents-telegram-app\services\llm_client_service\.storage\key\deepseek\deepseek_auth_key.json
2025-09-08 02:34:13,632 - app.llm_client.deepseek.llm_client_deepseek - ERROR - [llm_client_deepseek.py:72 - _validate()] - Failed to validate DeepSeekClient error: Keys file not found: D:\ART\InnodivingPro\MVP1.8.1\AI-assistant-for-patents-telegram-app\services\llm_client_service\.storage\key\deepseek\deepseek_auth_key.json
2025-09-08 02:34:13,652 - app.llm_client.deepseek.llm_client_deepseek - ERROR - [llm_client_deepseek.py:72 - _validate()] - Failed to validate DeepSeekClient error: Keys file not found: D:\ART\InnodivingPro\MVP1.8.1\AI-assistant-for-patents-telegram-app\services\llm_client_service\.storage\key\deepseek\deepseek_auth_key.json
2025-09-08 02:34:13,673 - app.llm_client.deepseek.llm_client_deepseek - ERROR - [llm_client_deepseek.py:72 - _validate()] - Failed to validate DeepSeekClient error: Keys file not found: D:\ART\InnodivingPro\MVP1.8.1\AI-assistant-for-patents-telegram-app\services\llm_client_service\.storage\key\deepseek\deepseek_auth_key.json
2025-09-08 02:34:13,690 - app.llm_client.deepseek.llm_client_deepseek - ERROR - [llm_client_deepseek.py:72 - _validate()] - Failed to validate DeepSeekClient error: Keys file not found: D:\ART\InnodivingPro\MVP1.8.1\AI-assistant-for-patents-telegram-app\services\llm_client_service\.storage\key\deepseek\deepseek_auth_key.json
2025-09-08 02:34:13,710 - app.llm_client.deepseek.llm_client_deepseek - ERROR - [llm_client_deepseek.py:72 - _validate()] - Failed to validate DeepSeekClient error: Keys file not found: D:\ART\InnodivingPro\MVP1.8.1\AI-assistant-for-patents-telegram-app\services\llm_client_service\.storage\key\deepseek\deepseek_auth_key.json
2025-09-08 02:35:26,534 - app.llm_client.deepseek.llm_client_deepseek - ERROR - [llm_client_deepseek.py:72 - _validate()] - Failed to validate DeepSeekClient error: Keys file not found: D:\ART\InnodivingPro\MVP1.8.1\AI-assistant-for-patents-telegram-app\services\llm_client_service\.storage\key\deepseek\deepseek_auth_key.json
2025-09-08 02:35:26,545 - app.llm_client.deepseek.llm_client_deepseek - ERROR - [llm_client_deepseek.py:72 - _validate()] - Failed to validate DeepSeekClient error: Keys file not found: D:\ART\InnodivingPro\MVP1.8.1\AI-assistant-for-patents-telegram-app\services\llm_client_service\.storage\key\deepseek\deepseek_auth_key.json
2025-09-08 02:35:26,553 - app.llm_client.deepseek.llm_client_deepseek - ERROR - [llm_client_deepseek.py:72 - _validate()] - Failed to validate DeepSeekClient error: Keys file not found: D:\ART\InnodivingPro\MVP1.8.1\AI-assistant-for-patents-telegram-app\services\llm_client_service\.storage\key\deepseek\deepseek_auth_key.json
2025-09-08 02:35:26,559 - app.llm_client.deepseek.llm_client_deepseek - ERROR - [llm_client_deepseek.py:72 - _validate()] - Failed to validate DeepSeekClient error: Keys file not found: D:\ART\InnodivingPro\MVP1.8.1\AI-assistant-for-patents-telegram-app\services\llm_client_service\.storage\key\deepseek\deepseek_auth_key.json
2025-09-08 02:35:26,567 - app.llm_client.deepseek.llm_client_deepseek - ERROR - [llm_client_deepseek.py:72 - _validate()] - Failed to validate DeepSeekClient error: Keys file not found: D:\ART\InnodivingPro\MVP1.8.1\AI-assistant-for-patents-telegram-app\services\llm_client_service\.storage\key\deepseek\deepseek_auth_key.json
2025-09-18 17:59:19,168 - app.llm_client.deepseek.llm_client_ws_deepseek - ERROR - [llm_client_ws_deepseek.py:82 - ask()] - Response ai: 402, {"error":{"message":"This request requires more credits, or fewer max_tokens. You requested up to 105463 tokens, but can only afford 22783. To increase, visit https://openrouter.ai/settings/credits and upgrade to a paid account","code":402,"metadata":{"provider_name":null}},"user_id":"user_30HzDxuKJmywx2RFEMmKp9Bgsx8"}
2025-09-18 22:15:26,470 - app.llm_client.deepseek.llm_client_ws_deepseek - ERROR - [llm_client_ws_deepseek.py:82 - ask()] - Response ai: 402, {"error":{"message":"This request requires more credits, or fewer max_tokens. You requested up to 105463 tokens, but can only afford 22783. To increase, visit https://openrouter.ai/settings/credits and upgrade to a paid account","code":402,"metadata":{"provider_name":null}},"user_id":"user_30HzDxuKJmywx2RFEMmKp9Bgsx8"}
2025-09-18 22:17:10,506 - app.llm_client.deepseek.llm_client_ws_deepseek - ERROR - [llm_client_ws_deepseek.py:82 - ask()] - Response ai: 402, {"error":{"message":"This request requires more credits, or fewer max_tokens. You requested up to 105463 tokens, but can only afford 22783. To increase, visit https://openrouter.ai/settings/credits and upgrade to a paid account","code":402,"metadata":{"provider_name":null}},"user_id":"user_30HzDxuKJmywx2RFEMmKp9Bgsx8"}
2025-09-18 22:28:02,691 - app.llm_client.deepseek.llm_client_ws_deepseek - ERROR - [llm_client_ws_deepseek.py:82 - ask()] - Response ai: 402, {"error":{"message":"This request requires more credits, or fewer max_tokens. You requested up to 105463 tokens, but can only afford 22783. To increase, visit https://openrouter.ai/settings/credits and upgrade to a paid account","code":402,"metadata":{"provider_name":null}},"user_id":"user_30HzDxuKJmywx2RFEMmKp9Bgsx8"}
2025-09-18 22:33:15,385 - app.llm_client.deepseek.llm_client_ws_deepseek - ERROR - [llm_client_ws_deepseek.py:82 - ask()] - Response ai: 402, {"error":{"message":"This request requires more credits, or fewer max_tokens. You requested up to 113071 tokens, but can only afford 22783. To increase, visit https://openrouter.ai/settings/credits and upgrade to a paid account","code":402,"metadata":{"provider_name":null}},"user_id":"user_30HzDxuKJmywx2RFEMmKp9Bgsx8"}
2025-09-18 22:33:55,749 - app.llm_client.deepseek.llm_client_ws_deepseek - ERROR - [llm_client_ws_deepseek.py:82 - ask()] - Response ai: 402, {"error":{"message":"This request requires more credits, or fewer max_tokens. You requested up to 113071 tokens, but can only afford 22783. To increase, visit https://openrouter.ai/settings/credits and upgrade to a paid account","code":402,"metadata":{"provider_name":null}},"user_id":"user_30HzDxuKJmywx2RFEMmKp9Bgsx8"}
2025-09-25 20:12:13,501 - app.llm_client.deepseek.llm_client_ws_deepseek - ERROR - [llm_client_ws_deepseek.py:82 - ask()] - Response ai: 402, {"error":{"message":"This request requires more credits, or fewer max_tokens. You requested up to 108932 tokens, but can only afford 22783. To increase, visit https://openrouter.ai/settings/credits and upgrade to a paid account","code":402,"metadata":{"provider_name":null}},"user_id":"user_30HzDxuKJmywx2RFEMmKp9Bgsx8"}
2025-09-25 20:13:38,428 - app.llm_client.deepseek.llm_client_ws_deepseek - ERROR - [llm_client_ws_deepseek.py:82 - ask()] - Response ai: 402, {"error":{"message":"This request requires more credits, or fewer max_tokens. You requested up to 108932 tokens, but can only afford 22783. To increase, visit https://openrouter.ai/settings/credits and upgrade to a paid account","code":402,"metadata":{"provider_name":null}},"user_id":"user_30HzDxuKJmywx2RFEMmKp9Bgsx8"}
2025-09-25 20:39:07,312 - app.llm_client.deepseek.llm_client_ws_deepseek - ERROR - [llm_client_ws_deepseek.py:82 - ask()] - Response ai: 402, {"error":{"message":"This request requires more credits, or fewer max_tokens. You requested up to 108932 tokens, but can only afford 22929. To increase, visit https://openrouter.ai/settings/credits and upgrade to a paid account","code":402,"metadata":{"provider_name":null}},"user_id":"user_31CM7LjZok3JGPvr2rhV1l0kytG"}
2025-09-25 20:39:32,770 - app.llm_client.deepseek.llm_client_ws_deepseek - ERROR - [llm_client_ws_deepseek.py:82 - ask()] - Response ai: 402, {"error":{"message":"This request requires more credits, or fewer max_tokens. You requested up to 108932 tokens, but can only afford 22929. To increase, visit https://openrouter.ai/settings/credits and upgrade to a paid account","code":402,"metadata":{"provider_name":null}},"user_id":"user_31CM7LjZok3JGPvr2rhV1l0kytG"}
2025-09-25 20:40:22,575 - app.llm_client.deepseek.llm_client_ws_deepseek - ERROR - [llm_client_ws_deepseek.py:82 - ask()] - Response ai: 402, {"error":{"message":"This request requires more credits, or fewer max_tokens. You requested up to 108932 tokens, but can only afford 22929. To increase, visit https://openrouter.ai/settings/credits and upgrade to a paid account","code":402,"metadata":{"provider_name":null}},"user_id":"user_31CM7LjZok3JGPvr2rhV1l0kytG"}
2025-09-26 08:57:42,452 - app.llm_client.deepseek.llm_client_ws_deepseek - ERROR - [llm_client_ws_deepseek.py:82 - ask()] - Response ai: 429, {"error":{"message":"Provider returned error","code":429,"metadata":{"raw":"deepseek/deepseek-chat-v3.1:free is temporarily rate-limited upstream. Please retry shortly, or add your own key to accumulate your rate limits: https://openrouter.ai/settings/integrations","provider_name":"DeepInfra"}},"user_id":"user_30HzDxuKJmywx2RFEMmKp9Bgsx8"}
2025-09-26 08:57:42,457 - app.llm_client.deepseek.llm_client_ws_deepseek - ERROR - [llm_client_ws_deepseek.py:82 - ask()] - Response ai: 429, {"error":{"message":"Provider returned error","code":429,"metadata":{"raw":"deepseek/deepseek-chat-v3.1:free is temporarily rate-limited upstream. Please retry shortly, or add your own key to accumulate your rate limits: https://openrouter.ai/settings/integrations","provider_name":"DeepInfra"}},"user_id":"user_30HzDxuKJmywx2RFEMmKp9Bgsx8"}
2025-09-26 08:57:43,582 - app.llm_client.deepseek.llm_client_ws_deepseek - ERROR - [llm_client_ws_deepseek.py:82 - ask()] - Response ai: 429, {"error":{"message":"Provider returned error","code":429,"metadata":{"raw":"deepseek/deepseek-chat-v3.1:free is temporarily rate-limited upstream. Please retry shortly, or add your own key to accumulate your rate limits: https://openrouter.ai/settings/integrations","provider_name":"DeepInfra"}},"user_id":"user_30HzDxuKJmywx2RFEMmKp9Bgsx8"}
2025-09-26 16:24:26,990 - app.llm_client.deepseek.llm_client_ws_deepseek - ERROR - [llm_client_ws_deepseek.py:82 - ask()] - Response ai: 429, {"error":{"message":"Provider returned error","code":429,"metadata":{"raw":"deepseek/deepseek-r1:free is temporarily rate-limited upstream. Please retry shortly, or add your own key to accumulate your rate limits: https://openrouter.ai/settings/integrations","provider_name":"Chutes"}},"user_id":"user_30HzDxuKJmywx2RFEMmKp9Bgsx8"}
2025-09-26 16:25:36,534 - app.llm_client.deepseek.llm_client_ws_deepseek - ERROR - [llm_client_ws_deepseek.py:82 - ask()] - Response ai: 429, {"error":{"message":"Provider returned error","code":429,"metadata":{"raw":"deepseek/deepseek-r1:free is temporarily rate-limited upstream. Please retry shortly, or add your own key to accumulate your rate limits: https://openrouter.ai/settings/integrations","provider_name":"Chutes"}},"user_id":"user_31CMYILPzflpX9WvAFW43Xrf6th"}
2025-09-26 16:26:16,179 - app.llm_client.deepseek.llm_client_ws_deepseek - ERROR - [llm_client_ws_deepseek.py:82 - ask()] - Response ai: 429, {"error":{"message":"Provider returned error","code":429,"metadata":{"raw":"deepseek/deepseek-r1:free is temporarily rate-limited upstream. Please retry shortly, or add your own key to accumulate your rate limits: https://openrouter.ai/settings/integrations","provider_name":"Chutes"}},"user_id":"user_30HzDxuKJmywx2RFEMmKp9Bgsx8"}
2025-09-26 16:26:43,025 - app.llm_client.deepseek.llm_client_ws_deepseek - ERROR - [llm_client_ws_deepseek.py:82 - ask()] - Response ai: 429, {"error":{"message":"Provider returned error","code":429,"metadata":{"raw":"deepseek/deepseek-r1:free is temporarily rate-limited upstream. Please retry shortly, or add your own key to accumulate your rate limits: https://openrouter.ai/settings/integrations","provider_name":"Chutes"}},"user_id":"user_31CM7LjZok3JGPvr2rhV1l0kytG"}
2025-09-26 16:34:22,416 - app.llm_client.deepseek.llm_client_ws_deepseek - ERROR - [llm_client_ws_deepseek.py:82 - ask()] - Response ai: 429, {"error":{"message":"Provider returned error","code":429,"metadata":{"raw":"deepseek/deepseek-r1:free is temporarily rate-limited upstream. Please retry shortly, or add your own key to accumulate your rate limits: https://openrouter.ai/settings/integrations","provider_name":"Chutes"}},"user_id":"user_31CLYfn3icF625pYys04slG4W0R"}
2025-09-26 16:34:37,627 - app.llm_client.deepseek.llm_client_ws_deepseek - ERROR - [llm_client_ws_deepseek.py:82 - ask()] - Response ai: 429, {"error":{"message":"Provider returned error","code":429,"metadata":{"raw":"deepseek/deepseek-r1:free is temporarily rate-limited upstream. Please retry shortly, or add your own key to accumulate your rate limits: https://openrouter.ai/settings/integrations","provider_name":"Chutes"}},"user_id":"user_33Edv0hubApG338qBr9yDClql6l"}
2025-09-26 16:35:02,887 - app.llm_client.deepseek.llm_client_ws_deepseek - ERROR - [llm_client_ws_deepseek.py:82 - ask()] - Response ai: 429, {"error":{"message":"Provider returned error","code":429,"metadata":{"raw":"deepseek/deepseek-r1:free is temporarily rate-limited upstream. Please retry shortly, or add your own key to accumulate your rate limits: https://openrouter.ai/settings/integrations","provider_name":"Chutes"}},"user_id":"user_33Edv0hubApG338qBr9yDClql6l"}
2025-09-28 21:07:10,015 - app.llm_client.deepseek.llm_client_deepseek - ERROR - [llm_client_deepseek.py:70 - _validate()] - Failed to validate DeepSeekClient error: Keys file not found: D:\ART\InnodivingPro\MVP1.8.1\AI-assistant-for-patents-telegram-app\services\llm_client_service\storage\key\gigachat\gigachat_jwt_token.json
2025-09-28 21:15:16,100 - app.llm_client.gigachat.llm_client_gigachat - ERROR - [llm_client_gigachat.py:33 - _validate()] - Failed to validate GigachatClient: Keys file not found: D:\ART\InnodivingPro\MVP1.8.1\AI-assistant-for-patents-telegram-app\services\llm_client_service\storage\key\gigachat\gigachat_jwt_token.json
2025-09-28 21:20:28,444 - core.token_manager.gigachat - ERROR - [gigachat.py:68 - get_token()] - Error running async update: asyncio.run() cannot be called from a running event loop
2025-09-28 21:20:28,449 - core.token_manager.gigachat - ERROR - [gigachat.py:80 - get_token()] - Error getting new token: asyncio.run() cannot be called from a running event loop
2025-09-28 21:20:28,449 - core.token_manager.gigachat - ERROR - [gigachat.py:81 - get_token()] - No available Gigachat API tokens
2025-09-28 21:20:28,449 - app.llm_client.llm_client - ERROR - [llm_client.py:26 - validate_token()] - Failed to validate token_or_error
2025-09-28 21:20:28,449 - app.llm_client.gigachat.llm_client_gigachat - ERROR - [llm_client_gigachat.py:33 - _validate()] - Failed to validate GigachatClient: exceptions must derive from BaseException
2025-09-28 21:33:55,073 - core.token_manager.gigachat - ERROR - [gigachat.py:123 - _update_jwt()] - HTTP client error in update_jwt: HTTPSConnectionPool(host='ngw.devices.sberbank.ru', port=9443): Max retries exceeded with url: /api/v2/oauth (Caused by SSLError(SSLCertVerificationError(1, '[SSL: CERTIFICATE_VERIFY_FAILED] certificate verify failed: self-signed certificate in certificate chain (_ssl.c:1028)')))
2025-09-28 21:33:55,073 - core.token_manager.gigachat - ERROR - [gigachat.py:69 - get_token()] - No available Gigachat API tokens
2025-09-28 21:33:55,074 - app.llm_client.llm_client - ERROR - [llm_client.py:26 - validate_token()] - Failed to validate token_or_error
2025-09-28 21:33:55,074 - app.llm_client.gigachat.llm_client_gigachat - ERROR - [llm_client_gigachat.py:33 - _validate()] - Failed to validate GigachatClient: exceptions must derive from BaseException
2025-09-28 21:41:41,339 - core.token_manager.gigachat - ERROR - [gigachat.py:126 - _update_jwt()] - HTTP client error in update_jwt: HTTPSConnectionPool(host='ngw.devices.sberbank.ru', port=9443): Max retries exceeded with url: /api/v2/oauth (Caused by SSLError(SSLCertVerificationError(1, '[SSL: CERTIFICATE_VERIFY_FAILED] certificate verify failed: self-signed certificate in certificate chain (_ssl.c:1028)')))
2025-09-28 21:41:41,340 - core.token_manager.gigachat - ERROR - [gigachat.py:71 - get_token()] - No available Gigachat API tokens
2025-09-28 21:41:41,340 - app.llm_client.llm_client - ERROR - [llm_client.py:26 - validate_token()] - Failed to validate token_or_error
2025-09-28 21:41:41,340 - app.llm_client.gigachat.llm_client_gigachat - ERROR - [llm_client_gigachat.py:33 - _validate()] - Failed to validate GigachatClient: exceptions must derive from BaseException
2025-09-29 00:22:11,946 - app.llm_client.gigachat.ws_gigachat - ERROR - [ws_gigachat.py:81 - ask()] - Response ai: 401, {"status":401,"message":"Token has expired"}

2025-09-29 00:23:41,012 - app.llm_client.gigachat.ws_gigachat - ERROR - [ws_gigachat.py:81 - ask()] - Response ai: 401, {"status":401,"message":"Token has expired"}

2025-09-29 17:17:11,678 - core.token_manager.gigachat - ERROR - [gigachat.py:126 - _update_jwt()] - HTTP client error in update_jwt: Invalid leading whitespace, reserved character(s), or return character(s) in header value: 'Basic \nMDE5OThhM2YtMjMwNC03NzBiLWJhNGItNDc5NWE0ODkxZDEwOmJkNTk1MGYzLTFhNmMtNDI3OC1hYmI5LWMxNWI2OTUzN2NhMw=='
2025-09-29 17:17:11,680 - core.token_manager.gigachat - ERROR - [gigachat.py:71 - get_token()] - No available Gigachat API tokens
2025-09-29 17:17:11,681 - app.llm_client.llm_client - ERROR - [llm_client.py:26 - validate_token()] - Failed to validate token_or_error
2025-09-29 17:17:11,681 - app.llm_client.gigachat.llm_client_gigachat - ERROR - [llm_client_gigachat.py:33 - _validate()] - Failed to validate GigachatClient: Failed to validate token_or_error
2025-10-02 20:39:20,184 - app.llm_client.deepseek.llm_client_deepseek - ERROR - [llm_client_deepseek.py:70 - _validate()] - Failed to validate DeepSeekClient error: cannot unpack non-iterable coroutine object
2025-10-03 14:58:55,840 - app.llm_client.deepseek.ws_deepseek - ERROR - [ws_deepseek.py:81 - ask()] - Response ai: 401, {"error":{"message":"No auth credentials found","code":401}}
2025-10-03 14:58:58,445 - app.llm_client.deepseek.ws_deepseek - ERROR - [ws_deepseek.py:81 - ask()] - Response ai: 401, {"error":{"message":"No auth credentials found","code":401}}
2025-10-03 14:58:59,566 - app.llm_client.deepseek.ws_deepseek - ERROR - [ws_deepseek.py:81 - ask()] - Response ai: 401, {"error":{"message":"No auth credentials found","code":401}}
2025-10-03 15:03:12,036 - app.llm_client.deepseek.ws_deepseek - ERROR - [ws_deepseek.py:81 - ask()] - Response ai: 401, {"error":{"message":"No auth credentials found","code":401}}
2025-10-03 15:03:13,621 - app.llm_client.deepseek.ws_deepseek - ERROR - [ws_deepseek.py:81 - ask()] - Response ai: 401, {"error":{"message":"No auth credentials found","code":401}}
2025-10-03 15:03:14,704 - app.llm_client.deepseek.ws_deepseek - ERROR - [ws_deepseek.py:81 - ask()] - Response ai: 401, {"error":{"message":"No auth credentials found","code":401}}
2025-10-03 15:34:11,920 - app.llm_client.deepseek.ws_deepseek - ERROR - [ws_deepseek.py:79 - ask()] - Connection to AI failed: 'NoneType' object is not subscriptable
2025-10-03 16:42:02,767 - app.llm_client.gigachat.ws_gigachat - ERROR - [ws_gigachat.py:81 - ask()] - Response ai: 402, {"status":402,"message":"Payment Required"}

2025-10-03 16:42:03,489 - app.llm_client.gigachat.ws_gigachat - ERROR - [ws_gigachat.py:81 - ask()] - Response ai: 402, {"status":402,"message":"Payment Required"}

2025-10-03 16:42:04,167 - app.llm_client.gigachat.ws_gigachat - ERROR - [ws_gigachat.py:81 - ask()] - Response ai: 402, {"status":402,"message":"Payment Required"}

2025-10-03 16:42:04,964 - app.llm_client.gigachat.ws_gigachat - ERROR - [ws_gigachat.py:81 - ask()] - Response ai: 402, {"status":402,"message":"Payment Required"}

2025-10-03 16:42:05,630 - app.llm_client.gigachat.ws_gigachat - ERROR - [ws_gigachat.py:81 - ask()] - Response ai: 402, {"status":402,"message":"Payment Required"}

2025-10-03 16:42:06,252 - app.llm_client.gigachat.ws_gigachat - ERROR - [ws_gigachat.py:81 - ask()] - Response ai: 402, {"status":402,"message":"Payment Required"}

2025-10-03 16:42:06,976 - app.llm_client.gigachat.ws_gigachat - ERROR - [ws_gigachat.py:81 - ask()] - Response ai: 402, {"status":402,"message":"Payment Required"}

2025-10-03 16:42:07,607 - app.llm_client.gigachat.ws_gigachat - ERROR - [ws_gigachat.py:81 - ask()] - Response ai: 402, {"status":402,"message":"Payment Required"}

2025-10-03 16:42:08,278 - app.llm_client.gigachat.ws_gigachat - ERROR - [ws_gigachat.py:81 - ask()] - Response ai: 402, {"status":402,"message":"Payment Required"}

2025-10-03 18:20:08,375 - app.llm_client.deepseek.ws_deepseek - ERROR - [ws_deepseek.py:79 - ask()] - Connection to AI failed: 
2025-10-03 18:45:30,973 - app.llm_client.deepseek.ws_deepseek - ERROR - [ws_deepseek.py:79 - ask()] - Connection to AI failed: 'NoneType' object is not subscriptable
